<?xml version="1.0"?>
<robot xmlns:xacro="http://www.ros.org/wiki/xacro"  name="robot">

<xacro:include filename="robot_include.xacro" />

<link name="world"> </link>

<joint name="base_joint" type="fixed">
    <origin xyz="0.0 0.0 0.0" rpy="0.0 0.0 0.0"/>
    <parent link="world"/>
    <child link="base_link"/>
    
</joint>

<link name="base_link">
    <visual>
        <origin xyz="0.0 0.0 0.05" rpy="0.0 0.0 0.0"/>
        <geometry>
            <box size="1 0.15 0.1"/> 
        </geometry>
        <material name="blue"/>
    </visual>
    <collision>
        <origin xyz="0.0 0.0 0.05" rpy="0.0 0.0 0.0"/>
        <geometry>
            <box size="1 0.15 0.1"/> 
        </geometry>
    </collision>
    <xacro:inertial_box mass="5" x="1" y="0.15" z="0.1">
        <origin xyz="0.0 0.0 0.05" rpy="0.0 0.0 0.0"/>
    </xacro:inertial_box>
</link>

<joint name="slider_joint" type="prismatic">
    <origin xyz="0.0 0.0 0.1" rpy="0.0 0.0 0.0"/>
    <parent link="base_link"/>
    <child link="slider_link"/>
    <axis xyz="1 0 0"/>
    <limit lower="-0.4" upper="0.4" velocity="100" effort="100"/> 
    <dynamics damping="10.0" friction="10.0"/>
    
</joint>

<link name="slider_link">
    <visual>
        <origin xyz="0.0 0.0 0.025" rpy="0.0 0.0 0.0"/>
        <geometry>
            <box size="0.1 0.1 0.05"/>
        </geometry>
        <material name="red"/>

    </visual>
    <collision>
        <origin xyz="0.0 0.0 0.025" rpy="0.0 0.0 0.0"/>
        <geometry>
            <box size="0.1 0.1 0.05"/>
        </geometry>
    </collision>
    <xacro:inertial_box mass="0.75" x="0.1" y="0.1" z="0.05">
        <origin xyz="0.0 0.0 0.025" rpy="0.0 0.0 0.0"/>
    </xacro:inertial_box>
</link>

<joint name="rotor_joint" type="revolute">
    <origin xyz="0.0 0.0 0.05" rpy="0.0 0.0 0.0"/>
    <parent link="slider_link"/>
    <child link="rotor_link"/>
    <axis xyz="0.0 0.0 1"/>
    <limit lower="${-pi}" upper="${pi}" effort="100" velocity="100"/>
    <dynamics friction="10.0"/>
    

</joint>

<link name="rotor_link">
    <visual>
        <origin xyz="0.0 0.0 0.0125" rpy="0.0 0.0 0.0"/>
        <geometry>
            <cylinder radius="0.04" length="0.025"/>
        </geometry>
        <material name="white"/>
    </visual>
    <collision>
        <origin xyz="0.0 0.0 0.0125" rpy="0.0 0.0 0.0"/>
        <geometry>
            <cylinder radius="0.04" length="0.025"/>
        </geometry>
    </collision>
    <xacro:inertial_cylinder mass="0.5" length="0.025" radius="0.04">
        <origin xyz="0.0 0.0 0.0125" rpy="0.0 0.0 0.0"/>
    </xacro:inertial_cylinder>

</link>

<joint name="arm_joint" type="revolute">
    <origin xyz="0.0 0.0 -0.0125" rpy="0.0 0.0 0.0"/>
    <parent link="rotor_link"/>
    <child link="arm_link"/>
    <axis xyz="0.0 -1 0.0"/>
    <limit lower="${-pi/6}" upper="${-pi/2}" effort="100" velocity="100"/>
    <dynamics friction="10.0"/>
    
</joint>

<link name="arm_link">
    <visual>
        <origin xyz="-0.02 0.0 0.25" rpy="0.0 0.0 0.0"/>
        <geometry>
            <box size="0.04 0.04 0.5"/>
        </geometry>
        <material name="orange"/>
    </visual>
    <collision>
        <origin xyz="-0.02 0.0 0.25" rpy="0.0 0.0 0.0"/>
        <geometry>
            <box size="0.04 0.04 0.5"/>
        </geometry>
    </collision>
    <xacro:inertial_box mass="0.5" x="0.04" y="0.04" z="0.5">
        <origin xyz="-0.02 0.0 0.25" rpy="0.0 0.0 0.0"/>
    </xacro:inertial_box>
    
    
</link>

<joint name="camera_joint" type="fixed">
    <origin xyz="-0.02 0.0 0.5" rpy="0.0 0.0 0.0"/>
    <parent link="arm_link"/>
    <child link="camera_link"/>
    
    
</joint>

<link name="camera_link">
    <visual>
        <origin xyz="0.0 0.0 0.005" rpy="${pi/2} 0.0 0.0"/>
        <geometry>
            <cylinder radius="0.005" length="0.02"/>
        </geometry>
        <material name="white"/>
    </visual>
    <visual>
        <origin xyz="0.0 0.0 0.015" rpy="0.0 0.0 0.0"/>
        <geometry>
            <box size="0.03 0.03 0.01"/>
        </geometry>
        <material name="white"/>
    </visual>
    <visual>
        <origin xyz="0.0 0.0 0.0225" rpy="0.0 0.0 0.0"/>
        <geometry>
            <cylinder radius="0.005" length="0.005"/>
        </geometry>
    </visual>
    <collision>
        <origin xyz="0.0 0.0 0.02" rpy="${pi/2} 0.0 0.0"/>
        <geometry>
            <box size="0.04 0.02 0.04"/>
        </geometry>
    </collision>
    <xacro:inertial_box mass="0.1" x="0.04" y="0.02" z="0.4">
        <origin xyz="0.0 0.0 0.02" rpy="0.0 0.0 0.0"/>
    </xacro:inertial_box>
    
</link>

<xacro:include filename="gazebo.xacro" />

</robot>